Workbook
Name a: [1]DicoRefFO!$A:$IV
Name AAA: [2]DicoRefFO!$1:$1048576
Name ATICA_DATA: #REF!
Name CAPE_DATA: #REF!
Name DicoRefFOTibco: #REF!
Name Field_Data_Types: #REF!
Name ListeMsg: '[3] ListeMessages'!$B$7:$E$180
Name ListeTypeEntite: [4]TypeEntite!$A$5:$A$18
Name Name: #REF!
Name TOTO: '[5]Data Elements Spreadsheet-GS'!#REF!
Name ZoneDicoRefFO: [3]DicoRefFO!$1:$1048576

Sheet Histo
A1: HISTORIQUE DES MODIFICATIONS
A2: Version | B2: Auteur | C2: Date | D2: Origine | E2: Description
A3: 25.13 | B3: A.Vounki | C3: 45777 | D3: Gestion | E3: remplacement de CodeSet par Codeset
A4: 25.13 | B4: A.MAVIOGHA | C4: 45777 | D4: CAPTURE | E4: Remplacement de l'attribut temp_stampingReference pour les objets fileData,remittanceData et transactionIdentification, par l'attribut stampingReference
A5: 25.13 | B5: A.MAVIOGHA | C5: 45777 | D5: TLP | E5: Modification du libellé de l'attribut ContryCode: Country à Acceptance System Contry Code
A7: 25.13 | B7: O.Addoum | C7: 45777 | D7: Emission | E7: Renommage attribut: cardContractDeferredCalendarCode --> cardAgreementDeferredCalendarCode cardContractCardAccountId --> cardAgreementAccountId cardContractEntityId --> cardAgreementEntityId cardContractEntityName --> cardAgreementEntityName cardContractId --> cardAgreementId internalRef --> internalReference Renommage codeset: cardContractCardDesignCode --> CardDesignCode CardContractDeferredCalendarCodeSet --> CardAgreementDeferredCalendarCodeSet Création de l'attribut : Environment.cardAgreement.requestId
A8: 25.13 | B8: A.Vounki | C8: 45777 | D8: Gestion | E8: Suppression du schemeMerchantId
A9: 25.13 | B9: A.MAVIOGHA | C9: 45777 | D9: CAPTURE | E9: Création de l'attribut stampingReference
A10: 25.13 | B10: A.MAVIOGHA | C10: 45777 | D10: TLP | E10: Création du Type temp_dialogTelerametrageFunctionCodeCodeset
A11: 25.13 | B11: A.MAVIOGHA | C11: 45777 | D11: TLP | E11: Correction du type de temp_versionCBCOM: Exact2NumericText en Exact2AlphaNumericText
A12: 25.13 | B12: A.MAVIOGHA | C12: 45777 | D12: TLP | E12: Création de l'attribut temp_dialogTelerametrageFunctionCode
A13: 25.13 | B13: B.Porcher | C13: 45776 | D13: Gestion | E13: merchantparameters.authorisedDuplicatedTransactions est de type Max4NumericText et pas Max999NumericText
A14: 25.13 | B14: B.Porcher | C14: 45776 | D14: Gestion | E14: Remplacement des 'é' par des 'e'
A15: 25.13 | B15: S.Lambert | C15: 45776 | D15: Contestation | E15: Revue des CodeSets : DisputeQualificationCodeset RefundDecisionCodeset RefundNatureCodeset StatusCodeCodeset
... A18: 25.13 | B18: A.MAVIOGHA | C18: 45776 | D18: CAPTURE | E18: L'attribut merchantProcessingId est obsolète
A19: 25.13 | B19: A.MAVIOGHA | C19: 29/04/205 | D19: CAPTURE | E19: L'attribut uniqueTransactionReference est obsolète
A20: 25.12 | B20: A.MAVIOGHA | C20: 45775 | D20: CAPTURE | E20: Création de l'attribut numberOfNonCompletedRemittanceTransactions
A21: 25.12 | B21: A.MAVIOGHA | C21: 45775 | D21: CAPTURE | E21: Création du Type ElectronicCommercelAuthentificationNatureCodeset
A22: 25.12 | B22: A.MAVIOGHA | C22: 45775 | D22: CAPTURE | E22: Création du Type TypeOfAdditionalDataCodeset
A23: 25.12 | B23: A.MAVIOGHA | C23: 45775 | D23: CAPTURE | E23: Création du Type AcceptanceSystemCurrentConnectingModeCodeset
A24: 25.12 | B24: A.MAVIOGHA | C24: 45775 | D24: CAPTURE | E24: Création du Type Exact10NumericText
A25: 25.12 | B25: A.MAVIOGHA | C25: 45775 | D25: CAPTURE | E25: Création de l'attribut debitwithTipNumber
A26: 25.12 | B26: A.MAVIOGHA | C26: 45775 | D26: CAPTURE | E26: Création de l'attribut debitwithTipAmount
A27: 25.12 | B27: A.MAVIOGHA | C27: 45775 | D27: CAPTURE | E27: Création de l'attribut totalTipAmount
A28: 25.12 | B28: A.MAVIOGHA | C28: 45775 | D28: CAPTURE | E28: Création de l'attribut debitwithDonationNumber
A29: 25.12 | B29: A.MAVIOGHA | C29: 45775 | D29: CAPTURE | E29: Création de l'attribut debitwithDonationAmount
A30: 25.12 | B30: A.MAVIOGHA | C30: 45775 | D30: CAPTURE | E30: Création de l'attribut totalDonationAmount
A31: 25.12 | B31: M.MARGHAD | C31: 45775 | D31: Référentiel commerçant | E31: Correction du type de authorisedDuplicatedTransactions : TrueFalseIndicator en Max999NumericText
... A82: 25.12 | B82: M.MARGHAD | C82: 45775 | D82: Référentiel commerçant | E82: Alimentation du CodeSet PaymentUseCaseCodeSet par : Quasi cash et Funds transfer,
A83: 25.12 | B83: A.MAVIOGHA | C83: 45771 | D83: TLP
A84: 25.12 | B84: A.MAVIOGHA | C84: 45771 | D84: TLP
A85: 25.12 | B85: A.MAVIOGHA | C85: 45771 | D85: TLP | E85: Création de l'attribut temp_alphabeticCodeOfCurrency1
A86: 25.12 | B86: A.MAVIOGHA | C86: 45771 | D86: TLP | E86: Création de l'attribut temp_conversionRate
A87: 25.12 | B87: A.MAVIOGHA | C87: 45771 | D87: TLP | E87: Création de l'attribut temp_languageAbbreviation
A88: 25.12 | B88: A.MAVIOGHA | C88: 45771 | D88: TLP | E88: Création de l'attribut temp_targetPercentageForRandomSelection
A89: 25.12 | B89: A.MAVIOGHA | C89: 45771 | D89: TLP | E89: Création de l'attribut temp_earlierGMTPeriod
A90: 25.12 | B90: A.MAVIOGHA | C90: 45771 | D90: TLP | E90: Création de l'attribut temp_laterGMTPeriod
A91: 25.12 | B91: A.MAVIOGHA | C91: 45771 | D91: TLP | E91: Création de l'attribut temp_gMTDifference
A92: 25.12 | B92: A.MAVIOGHA | C92: 45771 | D92: TLP | E92: Création de l'attribut temp_signOfTimeDifference
A93: 25.12 | B93: A.MAVIOGHA | C93: 45771 | D93: TLP | E93: Création de l'attribut temp_terminalApplicationVersionNumber
...

Sheet DICO_Export
C1: Champs calculés à partir de DICO_COMPLET
A2: Référence | B2: O/N | C2: Segment Message | D2: Object | E2: Attribute | F2: Type | G2: MinO | H2: MaxO | I2: Obsoletes | J2: Libellé | K2: CIFO | L2: CBAE | M2: CB2AF | N2: CB2A | O2: VISA | P2: MCD | Q2: Mainframe | R2: .
A3: 241112000000 | B3: O | C3: =VLOOKUP($A3,DICO_Complet!$A$3:$U$983,3,FALSE) -> ApiResponse | D3: =VLOOKUP($A3,DICO_Complet!$A$3:$U$983,4,FALSE) -> error | E3: =VLOOKUP($A3,DICO_Complet!$A$3:$U$983,5,FALSE) -> code | F3: =VLOOKUP($A3,DICO_Complet!$A$3:$U$983,6,FALSE) -> Max20Text | G3: =VLOOKUP($A3,DICO_Complet!$A$3:$U$983,7,FALSE) -> 0 | H3: =VLOOKUP($A3,DICO_Complet!$A$3:$U$983,8,FALSE) -> 0 | I3: =IF(VLOOKUP($A3,DICO_Complet!$A$3:$U$983,9,FALSE)<>0,VLOOKUP($A3,DICO_Complet!$A$3:$U$983,9,FALSE),"") | J3: =VLOOKUP($A3,DICO_Complet!$A$3:$U$983,10,FALSE) -> code | K3: =IF(VLOOKUP($A3,DICO_Complet!$A$3:$U$983,12,FALSE)=0,"",VLOOKUP($A3,DICO_Complet!$A$3:$U$983,12,FALSE)) | L3: =IF(VLOOKUP($A3,DICO_Complet!$A$3:$U$983,13,FALSE)=0,"",VLOOKUP($A3,DICO_Complet!$A$3:$U$983,13,FALSE)) | M3: =IF(VLOOKUP($A3,DICO_Complet!$A$3:$U$983,14,FALSE)=0,"",VLOOKUP($A3,DICO_Complet!$A$3:$U$983,14,FALSE)) | N3: =IF(VLOOKUP($A3,DICO_Complet!$A$3:$U$983,15,FALSE)=0,"",VLOOKUP($A3,DICO_Complet!$A$3:$U$983,15,FALSE)) | O3: =IF(VLOOKUP($A3,DICO_Complet!$A$3:$U$983,16,FALSE)=0,"",VLOOKUP($A3,DICO_Complet!$A$3:$U$983,16,FALSE)) | P3: =IF(VLOOKUP($A3,DICO_Complet!$A$3:$U$983,17,FALSE)=0,"",VLOOKUP($A3,DICO_Complet!$A$3:$U$983,17,FALSE)) | Q3: =IF(VLOOKUP($A3,DICO_Complet!$A$3:$U$983,18,FALSE)=0,"",VLOOKUP($A3,DICO_Complet!$A$3:$U$983,18,FALSE))
A4: 241112000001 | B4: O | C4: =VLOOKUP($A4,DICO_Complet!$A$3:$U$983,3,FALSE) -> ApiResponse | D4: =VLOOKUP($A4,DICO_Complet!$A$3:$U$983,4,FALSE) -> error | E4: =VLOOKUP($A4,DICO_Complet!$A$3:$U$983,5,FALSE) -> developerText | F4: =VLOOKUP($A4,DICO_Complet!$A$3:$U$983,6,FALSE) -> Max70Text | G4: =VLOOKUP($A4,DICO_Complet!$A$3:$U$983,7,FALSE) -> 0 | H4: =VLOOKUP($A4,DICO_Complet!$A$3:$U$983,8,FALSE) -> 0 | I4: =IF(VLOOKUP($A4,DICO_Complet!$A$3:$U$983,9,FALSE)<>0,VLOOKUP($A4,DICO_Complet!$A$3:$U$983,9,FALSE),"") | J4: =VLOOKUP($A4,DICO_Complet!$A$3:$U$983,10,FALSE) -> a text that explains the possible reason(s) of the error, and the possible corrections | K4: =IF(VLOOKUP($A4,DICO_Complet!$A$3:$U$983,12,FALSE)=0,"",VLOOKUP($A4,DICO_Complet!$A$3:$U$983,12,FALSE)) | L4: =IF(VLOOKUP($A4,DICO_Complet!$A$3:$U$983,13,FALSE)=0,"",VLOOKUP($A4,DICO_Complet!$A$3:$U$983,13,FALSE)) | M4: =IF(VLOOKUP($A4,DICO_Complet!$A$3:$U$983,14,FALSE)=0,"",VLOOKUP($A4,DICO_Complet!$A$3:$U$983,14,FALSE)) | N4: =IF(VLOOKUP($A4,DICO_Complet!$A$3:$U$983,15,FALSE)=0,"",VLOOKUP($A4,DICO_Complet!$A$3:$U$983,15,FALSE)) | O4: =IF(VLOOKUP($A4,DICO_Complet!$A$3:$U$983,16,FALSE)=0,"",VLOOKUP($A4,DICO_Complet!$A$3:$U$983,16,FALSE)) | P4: =IF(VLOOKUP($A4,DICO_Complet!$A$3:$U$983,17,FALSE)=0,"",VLOOKUP($A4,DICO_Complet!$A$3:$U$983,17,FALSE)) | Q4: =IF(VLOOKUP($A4,DICO_Complet!$A$3:$U$983,18,FALSE)=0,"",VLOOKUP($A4,DICO_Complet!$A$3:$U$983,18,FALSE))
A5: 241112000003 | B5: O | C5: =VLOOKUP($A5,DICO_Complet!$A$3:$U$983,3,FALSE) -> ApiResponse | D5: =VLOOKUP($A5,DICO_Complet!$A$3:$U$983,4,FALSE) -> error | E5: =VLOOKUP($A5,DICO_Complet!$A$3:$U$983,5,FALSE) -> moreInfo | F5: =VLOOKUP($A5,DICO_Complet!$A$3:$U$983,6,FALSE) -> Max256Text | G5: =VLOOKUP($A5,DICO_Complet!$A$3:$U$983,7,FALSE) -> 0 | H5: =VLOOKUP($A5,DICO_Complet!$A$3:$U$983,8,FALSE) -> 0 | I5: =IF(VLOOKUP($A5,DICO_Complet!$A$3:$U$983,9,FALSE)<>0,VLOOKUP($A5,DICO_Complet!$A$3:$U$983,9,FALSE),"") | J5: =VLOOKUP($A5,DICO_Complet!$A$3:$U$983,10,FALSE) -> URI to documents | K5: =IF(VLOOKUP($A5,DICO_Complet!$A$3:$U$983,12,FALSE)=0,"",VLOOKUP($A5,DICO_Complet!$A$3:$U$983,12,FALSE)) | L5: =IF(VLOOKUP($A5,DICO_Complet!$A$3:$U$983,13,FALSE)=0,"",VLOOKUP($A5,DICO_Complet!$A$3:$U$983,13,FALSE)) | M5: =IF(VLOOKUP($A5,DICO_Complet!$A$3:$U$983,14,FALSE)=0,"",VLOOKUP($A5,DICO_Complet!$A$3:$U$983,14,FALSE)) | N5: =IF(VLOOKUP($A5,DICO_Complet!$A$3:$U$983,15,FALSE)=0,"",VLOOKUP($A5,DICO_Complet!$A$3:$U$983,15,FALSE)) | O5: =IF(VLOOKUP($A5,DICO_Complet!$A$3:$U$983,16,FALSE)=0,"",VLOOKUP($A5,DICO_Complet!$A$3:$U$983,16,FALSE)) | P5: =IF(VLOOKUP($A5,DICO_Complet!$A$3:$U$983,17,FALSE)=0,"",VLOOKUP($A5,DICO_Complet!$A$3:$U$983,17,FALSE)) | Q5: =IF(VLOOKUP($A5,DICO_Complet!$A$3:$U$983,18,FALSE)=0,"",VLOOKUP($A5,DICO_Complet!$A$3:$U$983,18,FALSE))
A6: 241112000004 | B6: O | C6: =VLOOKUP($A6,DICO_Complet!$A$3:$U$983,3,FALSE) -> ApiResponse | D6: =VLOOKUP($A6,DICO_Complet!$A$3:$U$983,4,FALSE) -> error | E6: =VLOOKUP($A6,DICO_Complet!$A$3:$U$983,5,FALSE) -> text | F6: =VLOOKUP($A6,DICO_Complet!$A$3:$U$983,6,FALSE) -> Max40Text | G6: =VLOOKUP($A6,DICO_Complet!$A$3:$U$983,7,FALSE) -> 0 | H6: =VLOOKUP($A6,DICO_Complet!$A$3:$U$983,8,FALSE) -> 0 | I6: =IF(VLOOKUP($A6,DICO_Complet!$A$3:$U$983,9,FALSE)<>0,VLOOKUP($A6,DICO_Complet!$A$3:$U$983,9,FALSE),"") | J6: =VLOOKUP($A6,DICO_Complet!$A$3:$U$983,10,FALSE) -> short text that explains the error in a language that is useful for the end-user of the service | K6: =IF(VLOOKUP($A6,DICO_Complet!$A$3:$U$983,12,FALSE)=0,"",VLOOKUP($A6,DICO_Complet!$A$3:$U$983,12,FALSE)) | L6: =IF(VLOOKUP($A6,DICO_Complet!$A$3:$U$983,13,FALSE)=0,"",VLOOKUP($A6,DICO_Complet!$A$3:$U$983,13,FALSE)) | M6: =IF(VLOOKUP($A6,DICO_Complet!$A$3:$U$983,14,FALSE)=0,"",VLOOKUP($A6,DICO_Complet!$A$3:$U$983,14,FALSE)) | N6: =IF(VLOOKUP($A6,DICO_Complet!$A$3:$U$983,15,FALSE)=0,"",VLOOKUP($A6,DICO_Complet!$A$3:$U$983,15,FALSE)) | O6: =IF(VLOOKUP($A6,DICO_Complet!$A$3:$U$983,16,FALSE)=0,"",VLOOKUP($A6,DICO_Complet!$A$3:$U$983,16,FALSE)) | P6: =IF(VLOOKUP($A6,DICO_Complet!$A$3:$U$983,17,FALSE)=0,"",VLOOKUP($A6,DICO_Complet!$A$3:$U$983,17,FALSE)) | Q6: =IF(VLOOKUP($A6,DICO_Complet!$A$3:$U$983,18,FALSE)=0,"",VLOOKUP($A6,DICO_Complet!$A$3:$U$983,18,FALSE))
A7: 241112000002 | B7: O | C7: =VLOOKUP($A7,DICO_Complet!$A$3:$U$983,3,FALSE) -> ApiResponse | D7: =VLOOKUP($A7,DICO_Complet!$A$3:$U$983,4,FALSE) -> httpStatus | E7: =VLOOKUP($A7,DICO_Complet!$A$3:$U$983,5,FALSE) -> httpCode | F7: =VLOOKUP($A7,DICO_Complet!$A$3:$U$983,6,FALSE) -> Exact3NumericText | G7: =VLOOKUP($A7,DICO_Complet!$A$3:$U$983,7,FALSE) -> 0 | H7: =VLOOKUP($A7,DICO_Complet!$A$3:$U$983,8,FALSE) -> 0 | I7: =IF(VLOOKUP($A7,DICO_Complet!$A$3:$U$983,9,FALSE)<>0,VLOOKUP($A7,DICO_Complet!$A$3:$U$983,9,FALSE),"") | J7: =VLOOKUP($A7,DICO_Complet!$A$3:$U$983,10,FALSE) -> Status code http | K7: =IF(VLOOKUP($A7,DICO_Complet!$A$3:$U$983,12,FALSE)=0,"",VLOOKUP($A7,DICO_Complet!$A$3:$U$983,12,FALSE)) | L7: =IF(VLOOKUP($A7,DICO_Complet!$A$3:$U$983,13,FALSE)=0,"",VLOOKUP($A7,DICO_Complet!$A$3:$U$983,13,FALSE)) | M7: =IF(VLOOKUP($A7,DICO_Complet!$A$3:$U$983,14,FALSE)=0,"",VLOOKUP($A7,DICO_Complet!$A$3:$U$983,14,FALSE)) | N7: =IF(VLOOKUP($A7,DICO_Complet!$A$3:$U$983,15,FALSE)=0,"",VLOOKUP($A7,DICO_Complet!$A$3:$U$983,15,FALSE)) | O7: =IF(VLOOKUP($A7,DICO_Complet!$A$3:$U$983,16,FALSE)=0,"",VLOOKUP($A7,DICO_Complet!$A$3:$U$983,16,FALSE)) | P7: =IF(VLOOKUP($A7,DICO_Complet!$A$3:$U$983,17,FALSE)=0,"",VLOOKUP($A7,DICO_Complet!$A$3:$U$983,17,FALSE)) | Q7: =IF(VLOOKUP($A7,DICO_Complet!$A$3:$U$983,18,FALSE)=0,"",VLOOKUP($A7,DICO_Complet!$A$3:$U$983,18,FALSE))
A8: 250331114316 | B8: O | C8: =VLOOKUP($A8,DICO_Complet!$A$3:$U$983,3,FALSE) -> ApiResponse | D8: =VLOOKUP($A8,DICO_Complet!$A$3:$U$983,4,FALSE) -> httpStatus | E8: =VLOOKUP($A8,DICO_Complet!$A$3:$U$983,5,FALSE) -> requestId | F8: =VLOOKUP($A8,DICO_Complet!$A$3:$U$983,6,FALSE) -> Max36NumericText | G8: =VLOOKUP($A8,DICO_Complet!$A$3:$U$983,7,FALSE) -> 0 | H8: =VLOOKUP($A8,DICO_Complet!$A$3:$U$983,8,FALSE) -> 0 | I8: =IF(VLOOKUP($A8,DICO_Complet!$A$3:$U$983,9,FALSE)<>0,VLOOKUP($A8,DICO_Complet!$A$3:$U$983,9,FALSE),"") | J8: =VLOOKUP($A8,DICO_Complet!$A$3:$U$983,10,FALSE) -> Unique ID of API response | K8: =IF(VLOOKUP($A8,DICO_Complet!$A$3:$U$983,12,FALSE)=0,"",VLOOKUP($A8,DICO_Complet!$A$3:$U$983,12,FALSE)) | L8: =IF(VLOOKUP($A8,DICO_Complet!$A$3:$U$983,13,FALSE)=0,"",VLOOKUP($A8,DICO_Complet!$A$3:$U$983,13,FALSE)) | M8: =IF(VLOOKUP($A8,DICO_Complet!$A$3:$U$983,14,FALSE)=0,"",VLOOKUP($A8,DICO_Complet!$A$3:$U$983,14,FALSE)) | N8: =IF(VLOOKUP($A8,DICO_Complet!$A$3:$U$983,15,FALSE)=0,"",VLOOKUP($A8,DICO_Complet!$A$3:$U$983,15,FALSE)) | O8: =IF(VLOOKUP($A8,DICO_Complet!$A$3:$U$983,16,FALSE)=0,"",VLOOKUP($A8,DICO_Complet!$A$3:$U$983,16,FALSE)) | P8: =IF(VLOOKUP($A8,DICO_Complet!$A$3:$U$983,17,FALSE)=0,"",VLOOKUP($A8,DICO_Complet!$A$3:$U$983,17,FALSE)) | Q8: =IF(VLOOKUP($A8,DICO_Complet!$A$3:$U$983,18,FALSE)=0,"",VLOOKUP($A8,DICO_Complet!$A$3:$U$983,18,FALSE))
A9: 250331114321 | B9: O | C9: =VLOOKUP($A9,DICO_Complet!$A$3:$U$983,3,FALSE) -> Context | D9: =VLOOKUP($A9,DICO_Complet!$A$3:$U$983,4,FALSE) -> cardContext | E9: =VLOOKUP($A9,DICO_Complet!$A$3:$U$983,5,FALSE) -> acquiringChannel | F9: =VLOOKUP($A9,DICO_Complet!$A$3:$U$983,6,FALSE) -> AcquiringChannelCodeset | G9: =VLOOKUP($A9,DICO_Complet!$A$3:$U$983,7,FALSE) -> 0 | H9: =VLOOKUP($A9,DICO_Complet!$A$3:$U$983,8,FALSE) -> 0 | I9: =IF(VLOOKUP($A9,DICO_Complet!$A$3:$U$983,9,FALSE)<>0,VLOOKUP($A9,DICO_Complet!$A$3:$U$983,9,FALSE),"") | J9: =VLOOKUP($A9,DICO_Complet!$A$3:$U$983,10,FALSE) -> Indicates through which channel the action is triggered | K9: =IF(VLOOKUP($A9,DICO_Complet!$A$3:$U$983,12,FALSE)=0,"",VLOOKUP($A9,DICO_Complet!$A$3:$U$983,12,FALSE)) | L9: =IF(VLOOKUP($A9,DICO_Complet!$A$3:$U$983,13,FALSE)=0,"",VLOOKUP($A9,DICO_Complet!$A$3:$U$983,13,FALSE)) | M9: =IF(VLOOKUP($A9,DICO_Complet!$A$3:$U$983,14,FALSE)=0,"",VLOOKUP($A9,DICO_Complet!$A$3:$U$983,14,FALSE)) | N9: =IF(VLOOKUP($A9,DICO_Complet!$A$3:$U$983,15,FALSE)=0,"",VLOOKUP($A9,DICO_Complet!$A$3:$U$983,15,FALSE)) | O9: =IF(VLOOKUP($A9,DICO_Complet!$A$3:$U$983,16,FALSE)=0,"",VLOOKUP($A9,DICO_Complet!$A$3:$U$983,16,FALSE)) | P9: =IF(VLOOKUP($A9,DICO_Complet!$A$3:$U$983,17,FALSE)=0,"",VLOOKUP($A9,DICO_Complet!$A$3:$U$983,17,FALSE)) | Q9: =IF(VLOOKUP($A9,DICO_Complet!$A$3:$U$983,18,FALSE)=0,"",VLOOKUP($A9,DICO_Complet!$A$3:$U$983,18,FALSE))
A10: 241112000005 | B10: O | C10: =VLOOKUP($A10,DICO_Complet!$A$3:$U$983,3,FALSE) -> Context | D10: =VLOOKUP($A10,DICO_Complet!$A$3:$U$983,4,FALSE) -> cardContext | E10: =VLOOKUP($A10,DICO_Complet!$A$3:$U$983,5,FALSE) -> actionOnCard | F10: =VLOOKUP($A10,DICO_Complet!$A$3:$U$983,6,FALSE) -> ActivationCardCodeset | G10: =VLOOKUP($A10,DICO_Complet!$A$3:$U$983,7,FALSE) -> 0 | H10: =VLOOKUP($A10,DICO_Complet!$A$3:$U$983,8,FALSE) -> 0 | I10: =IF(VLOOKUP($A10,DICO_Complet!$A$3:$U$983,9,FALSE)<>0,VLOOKUP($A10,DICO_Complet!$A$3:$U$983,9,FALSE),"") | J10: =VLOOKUP($A10,DICO_Complet!$A$3:$U$983,10,FALSE) -> Action on card during transaction (activated, desactivated) | K10: =IF(VLOOKUP($A10,DICO_Complet!$A$3:$U$983,12,FALSE)=0,"",VLOOKUP($A10,DICO_Complet!$A$3:$U$983,12,FALSE)) -> AUT358/ AUT359 | L10: =IF(VLOOKUP($A10,DICO_Complet!$A$3:$U$983,13,FALSE)=0,"",VLOOKUP($A10,DICO_Complet!$A$3:$U$983,13,FALSE)) | M10: =IF(VLOOKUP($A10,DICO_Complet!$A$3:$U$983,14,FALSE)=0,"",VLOOKUP($A10,DICO_Complet!$A$3:$U$983,14,FALSE)) | N10: =IF(VLOOKUP($A10,DICO_Complet!$A$3:$U$983,15,FALSE)=0,"",VLOOKUP($A10,DICO_Complet!$A$3:$U$983,15,FALSE)) | O10: =IF(VLOOKUP($A10,DICO_Complet!$A$3:$U$983,16,FALSE)=0,"",VLOOKUP($A10,DICO_Complet!$A$3:$U$983,16,FALSE)) | P10: =IF(VLOOKUP($A10,DICO_Complet!$A$3:$U$983,17,FALSE)=0,"",VLOOKUP($A10,DICO_Complet!$A$3:$U$983,17,FALSE)) | Q10: =IF(VLOOKUP($A10,DICO_Complet!$A$3:$U$983,18,FALSE)=0,"",VLOOKUP($A10,DICO_Complet!$A$3:$U$983,18,FALSE))
A11: 250331162616 | B11: O | C11: =VLOOKUP($A11,DICO_Complet!$A$3:$U$983,3,FALSE) -> Context | D11: =VLOOKUP($A11,DICO_Complet!$A$3:$U$983,4,FALSE) -> cardContext | E11: =VLOOKUP($A11,DICO_Complet!$A$3:$U$983,5,FALSE) -> activationCodeForNoShowInvoice | F11: =VLOOKUP($A11,DICO_Complet!$A$3:$U$983,6,FALSE) -> Exact1AlphaNumericText | G11: =VLOOKUP($A11,DICO_Complet!$A$3:$U$983,7,FALSE) -> 0 | H11: =VLOOKUP($A11,DICO_Complet!$A$3:$U$983,8,FALSE) -> 0 | I11: =IF(VLOOKUP($A11,DICO_Complet!$A$3:$U$983,9,FALSE)<>0,VLOOKUP($A11,DICO_Complet!$A$3:$U$983,9,FALSE),"") | J11: =VLOOKUP($A11,DICO_Complet!$A$3:$U$983,10,FALSE) -> Activation code for no-show invoice | K11: =IF(VLOOKUP($A11,DICO_Complet!$A$3:$U$983,12,FALSE)=0,"",VLOOKUP($A11,DICO_Complet!$A$3:$U$983,12,FALSE)) | L11: =IF(VLOOKUP($A11,DICO_Complet!$A$3:$U$983,13,FALSE)=0,"",VLOOKUP($A11,DICO_Complet!$A$3:$U$983,13,FALSE)) | M11: =IF(VLOOKUP($A11,DICO_Complet!$A$3:$U$983,14,FALSE)=0,"",VLOOKUP($A11,DICO_Complet!$A$3:$U$983,14,FALSE)) -> 72_DF07 part 14 | N11: =IF(VLOOKUP($A11,DICO_Complet!$A$3:$U$983,15,FALSE)=0,"",VLOOKUP($A11,DICO_Complet!$A$3:$U$983,15,FALSE)) | O11: =IF(VLOOKUP($A11,DICO_Complet!$A$3:$U$983,16,FALSE)=0,"",VLOOKUP($A11,DICO_Complet!$A$3:$U$983,16,FALSE)) | P11: =IF(VLOOKUP($A11,DICO_Complet!$A$3:$U$983,17,FALSE)=0,"",VLOOKUP($A11,DICO_Complet!$A$3:$U$983,17,FALSE)) | Q11: =IF(VLOOKUP($A11,DICO_Complet!$A$3:$U$983,18,FALSE)=0,"",VLOOKUP($A11,DICO_Complet!$A$3:$U$983,18,FALSE))
A12: 250331162615 | B12: O | C12: =VLOOKUP($A12,DICO_Complet!$A$3:$U$983,3,FALSE) -> Context | D12: =VLOOKUP($A12,DICO_Complet!$A$3:$U$983,4,FALSE) -> cardContext | E12: =VLOOKUP($A12,DICO_Complet!$A$3:$U$983,5,FALSE) -> activCodePLBSInvoiceRemoteModeOrPreAuthProlongTransaction | F12: =VLOOKUP($A12,DICO_Complet!$A$3:$U$983,6,FALSE) -> Exact1AlphaNumericText | G12: =VLOOKUP($A12,DICO_Complet!$A$3:$U$983,7,FALSE) -> 0 | H12: =VLOOKUP($A12,DICO_Complet!$A$3:$U$983,8,FALSE) -> 0 | I12: =IF(VLOOKUP($A12,DICO_Complet!$A$3:$U$983,9,FALSE)<>0,VLOOKUP($A12,DICO_Complet!$A$3:$U$983,9,FALSE),"") | J12: =VLOOKUP($A12,DICO_Complet!$A$3:$U$983,10,FALSE) -> Activation code for invoice for the reservation and rental of goods or services in remote mode | K12: =IF(VLOOKUP($A12,DICO_Complet!$A$3:$U$983,12,FALSE)=0,"",VLOOKUP($A12,DICO_Complet!$A$3:$U$983,12,FALSE)) | L12: =IF(VLOOKUP($A12,DICO_Complet!$A$3:$U$983,13,FALSE)=0,"",VLOOKUP($A12,DICO_Complet!$A$3:$U$983,13,FALSE)) | M12: =IF(VLOOKUP($A12,DICO_Complet!$A$3:$U$983,14,FALSE)=0,"",VLOOKUP($A12,DICO_Complet!$A$3:$U$983,14,FALSE)) | N12: =IF(VLOOKUP($A12,DICO_Complet!$A$3:$U$983,15,FALSE)=0,"",VLOOKUP($A12,DICO_Complet!$A$3:$U$983,15,FALSE)) | O12: =IF(VLOOKUP($A12,DICO_Complet!$A$3:$U$983,16,FALSE)=0,"",VLOOKUP($A12,DICO_Complet!$A$3:$U$983,16,FALSE)) | P12: =IF(VLOOKUP($A12,DICO_Complet!$A$3:$U$983,17,FALSE)=0,"",VLOOKUP($A12,DICO_Complet!$A$3:$U$983,17,FALSE)) | Q12: =IF(VLOOKUP($A12,DICO_Complet!$A$3:$U$983,18,FALSE)=0,"",VLOOKUP($A12,DICO_Complet!$A$3:$U$983,18,FALSE))
A13: 250331162617 | B13: O | C13: =VLOOKUP($A13,DICO_Complet!$A$3:$U$983,3,FALSE) -> Context | D13: =VLOOKUP($A13,DICO_Complet!$A$3:$U$983,4,FALSE) -> cardContext | E13: =VLOOKUP($A13,DICO_Complet!$A$3:$U$983,5,FALSE) -> additionalInvoiceActivationCode | F13: =VLOOKUP($A13,DICO_Complet!$A$3:$U$983,6,FALSE) -> Exact1AlphaNumericText | G13: =VLOOKUP($A13,DICO_Complet!$A$3:$U$983,7,FALSE) -> 0 | H13: =VLOOKUP($A13,DICO_Complet!$A$3:$U$983,8,FALSE) -> 0 | I13: =IF(VLOOKUP($A13,DICO_Complet!$A$3:$U$983,9,FALSE)<>0,VLOOKUP($A13,DICO_Complet!$A$3:$U$983,9,FALSE),"") | J13: =VLOOKUP($A13,DICO_Complet!$A$3:$U$983,10,FALSE) -> Additional invoice activation code | K13: =IF(VLOOKUP($A13,DICO_Complet!$A$3:$U$983,12,FALSE)=0,"",VLOOKUP($A13,DICO_Complet!$A$3:$U$983,12,FALSE)) | L13: =IF(VLOOKUP($A13,DICO_Complet!$A$3:$U$983,13,FALSE)=0,"",VLOOKUP($A13,DICO_Complet!$A$3:$U$983,13,FALSE)) | M13: =IF(VLOOKUP($A13,DICO_Complet!$A$3:$U$983,14,FALSE)=0,"",VLOOKUP($A13,DICO_Complet!$A$3:$U$983,14,FALSE)) -> 72_DF07 part 13 | N13: =IF(VLOOKUP($A13,DICO_Complet!$A$3:$U$983,15,FALSE)=0,"",VLOOKUP($A13,DICO_Complet!$A$3:$U$983,15,FALSE)) | O13: =IF(VLOOKUP($A13,DICO_Complet!$A$3:$U$983,16,FALSE)=0,"",VLOOKUP($A13,DICO_Complet!$A$3:$U$983,16,FALSE)) | P13: =IF(VLOOKUP($A13,DICO_Complet!$A$3:$U$983,17,FALSE)=0,"",VLOOKUP($A13,DICO_Complet!$A$3:$U$983,17,FALSE)) | Q13: =IF(VLOOKUP($A13,DICO_Complet!$A$3:$U$983,18,FALSE)=0,"",VLOOKUP($A13,DICO_Complet!$A$3:$U$983,18,FALSE))
A14: 250410114322 | B14: O | C14: =VLOOKUP($A14,DICO_Complet!$A$3:$U$983,3,FALSE) -> Context | D14: =VLOOKUP($A14,DICO_Complet!$A$3:$U$983,4,FALSE) -> cardContext | E14: =VLOOKUP($A14,DICO_Complet!$A$3:$U$983,5,FALSE) -> blockingReasonCode | F14: =VLOOKUP($A14,DICO_Complet!$A$3:$U$983,6,FALSE) -> BlockingReasonCodeset | G14: =VLOOKUP($A14,DICO_Complet!$A$3:$U$983,7,FALSE) -> 0 | H14: =VLOOKUP($A14,DICO_Complet!$A$3:$U$983,8,FALSE) -> 0 | I14: =IF(VLOOKUP($A14,DICO_Complet!$A$3:$U$983,9,FALSE)<>0,VLOOKUP($A14,DICO_Complet!$A$3:$U$983,9,FALSE),"") | J14: =VLOOKUP($A14,DICO_Complet!$A$3:$U$983,10,FALSE) -> BlockingReasonCodeset | K14: =IF(VLOOKUP($A14,DICO_Complet!$A$3:$U$983,12,FALSE)=0,"",VLOOKUP($A14,DICO_Complet!$A$3:$U$983,12,FALSE)) | L14: =IF(VLOOKUP($A14,DICO_Complet!$A$3:$U$983,13,FALSE)=0,"",VLOOKUP($A14,DICO_Complet!$A$3:$U$983,13,FALSE)) | M14: =IF(VLOOKUP($A14,DICO_Complet!$A$3:$U$983,14,FALSE)=0,"",VLOOKUP($A14,DICO_Complet!$A$3:$U$983,14,FALSE)) | N14: =IF(VLOOKUP($A14,DICO_Complet!$A$3:$U$983,15,FALSE)=0,"",VLOOKUP($A14,DICO_Complet!$A$3:$U$983,15,FALSE)) | O14: =IF(VLOOKUP($A14,DICO_Complet!$A$3:$U$983,16,FALSE)=0,"",VLOOKUP($A14,DICO_Complet!$A$3:$U$983,16,FALSE)) | P14: =IF(VLOOKUP($A14,DICO_Complet!$A$3:$U$983,17,FALSE)=0,"",VLOOKUP($A14,DICO_Complet!$A$3:$U$983,17,FALSE)) | Q14: =IF(VLOOKUP($A14,DICO_Complet!$A$3:$U$983,18,FALSE)=0,"",VLOOKUP($A14,DICO_Complet!$A$3:$U$983,18,FALSE))
... A896: 241112000230 | B896: O | C896: =VLOOKUP($A896,DICO_Complet!$A$3:$U$983,3,FALSE) -> Transaction | D896: =VLOOKUP($A896,DICO_Complet!$A$3:$U$983,4,FALSE) -> transactionIdentification | E896: =VLOOKUP($A896,DICO_Complet!$A$3:$U$983,5,FALSE) -> transmissionGmtDateTime | F896: =VLOOKUP($A896,DICO_Complet!$A$3:$U$983,6,FALSE) -> ISODateTime | G896: =VLOOKUP($A896,DICO_Complet!$A$3:$U$983,7,FALSE) -> 0 | H896: =VLOOKUP($A896,DICO_Complet!$A$3:$U$983,8,FALSE) -> 0 | I896: =IF(VLOOKUP($A896,DICO_Complet!$A$3:$U$983,9,FALSE)<>0,VLOOKUP($A896,DICO_Complet!$A$3:$U$983,9,FALSE),"") | J896: =VLOOKUP($A896,DICO_Complet!$A$3:$U$983,10,FALSE) -> Transmission date and time GMT | K896: =IF(VLOOKUP($A896,DICO_Complet!$A$3:$U$983,12,FALSE)=0,"",VLOOKUP($A896,DICO_Complet!$A$3:$U$983,12,FALSE)) -> ISO7 | L896: =IF(VLOOKUP($A896,DICO_Complet!$A$3:$U$983,13,FALSE)=0,"",VLOOKUP($A896,DICO_Complet!$A$3:$U$983,13,FALSE)) -> [7] | M896: =IF(VLOOKUP($A896,DICO_Complet!$A$3:$U$983,14,FALSE)=0,"",VLOOKUP($A896,DICO_Complet!$A$3:$U$983,14,FALSE)) | N896: =IF(VLOOKUP($A896,DICO_Complet!$A$3:$U$983,15,FALSE)=0,"",VLOOKUP($A896,DICO_Complet!$A$3:$U$983,15,FALSE)) | O896: =IF(VLOOKUP($A896,DICO_Complet!$A$3:$U$983,16,FALSE)=0,"",VLOOKUP($A896,DICO_Complet!$A$3:$U$983,16,FALSE)) | P896: =IF(VLOOKUP($A896,DICO_Complet!$A$3:$U$983,17,FALSE)=0,"",VLOOKUP($A896,DICO_Complet!$A$3:$U$983,17,FALSE)) | Q896: =IF(VLOOKUP($A896,DICO_Complet!$A$3:$U$983,18,FALSE)=0,"",VLOOKUP($A896,DICO_Complet!$A$3:$U$983,18,FALSE))

Sheet DICO_Complet
A2: Référence | B2: N/A | C2: Segment Message | D2: Object | E2: Attribute | F2: Type | G2: N/A2 | H2: N/A3 | I2: Obsolète | J2: Libellé | K2: Commentaire | L2: CIFO | M2: CBAE | N2: CB2AF | O2: CB2A | P2: VISA | Q2: MCD | R2: Mainframe | S2: temp_ Data | T2: Demander PAR
A3: 241112000000 | B3: XXX | C3: ApiResponse | D3: error | E3: code | F3: Max20Text | J3: code
A4: 241112000001 | B4: XXX | C4: ApiResponse | D4: error | E4: developerText | F4: Max70Text | J4: a text that explains the possible reason(s) of the error, and the possible corrections
A5: 241112000003 | B5: XXX | C5: ApiResponse | D5: error | E5: moreInfo | F5: Max256Text | J5: URI to documents
A6: 241112000004 | B6: XXX | C6: ApiResponse | D6: error | E6: text | F6: Max40Text | J6: short text that explains the error in a language that is useful for the end-user of the service
A7: 241112000002 | B7: XXX | C7: ApiResponse | D7: httpStatus | E7: httpCode | F7: Exact3NumericText | J7: Status code http
A8: 250331114316 | B8: XXX | C8: ApiResponse | D8: httpStatus | E8: requestId | F8: Max36NumericText | J8: Unique ID of API response
A9: 250331114321 | B9: XXX | C9: Context | D9: cardContext | E9: acquiringChannel | F9: AcquiringChannelCodeset | J9: Indicates through which channel the action is triggered
A10: 241112000005 | B10: XXX | C10: Context | D10: cardContext | E10: actionOnCard | F10: ActivationCardCodeset | J10: Action on card during transaction (activated, desactivated) | K10: Activated, Desactivated or Nothing | L10: AUT358/ AUT359
A11: 250331162616 | B11: XXX | C11: Context | D11: cardContext | E11: activationCodeForNoShowInvoice | F11: Exact1AlphaNumericText | J11: Activation code for no-show invoice | N11: 72_DF07 part 14
A12: 250331162615 | B12: XXX | C12: Context | D12: cardContext | E12: activCodePLBSInvoiceRemoteModeOrPreAuthProlongTransaction | F12: Exact1AlphaNumericText | J12: Activation code for invoice for the reservation and rental of goods or services in remote mode
A13: 250331162617 | B13: XXX | C13: Context | D13: cardContext | E13: additionalInvoiceActivationCode | F13: Exact1AlphaNumericText | J13: Additional invoice activation code | N13: 72_DF07 part 13
A14: 250410114322 | B14: XXX | C14: Context | D14: cardContext | E14: blockingReasonCode | F14: BlockingReasonCodeset | J14: BlockingReasonCodeset
A15: 250410114323 | B15: XXX | C15: Context | D15: cardContext | E15: blockingRegulatoryReasonCode | F15: BlockingRegulatoryReasonCodeset | J15: BlockingRegulatoryReasonCodeset
A16: 250331114322 | B16: XXX | C16: Context | D16: cardContext | E16: contactlessActionCode | F16: TrueFalseIndicator | J16: Indicates if the contaclless feature is to be activated
A17: 250410114320 | B17: XXX | C17: Context | D17: cardContext | E17: contactlessActivationChoiceCode | F17: ContactlessActivationChoiceCodeset | J17: Choix activation du sans contact
A18: 250331162613 | B18: XXX | C18: Context | D18: cardContext | E18: forcingAuthorised | F18: Exact1AlphaNumericText | J18: Forcing Authorised
A19: 250331114323 | B19: XXX | C19: Context | D19: cardContext | E19: lockingActionCode | F19: TrueFalseIndicator | J19: indicates if the contract is blocked or not
A20: 250410114321 | B20: XXX | C20: Context | D20: cardContext | E20: lockingReasonCode | F20: LockingReasonCodeset | J20: LockingReasonCodeset
A21: 250331162610 | B21: XXX | C21: Context | D21: cardContext | E21: maximumLengthOfPAN | F21: Max2AlphaNumericText | J21: Maximum length of cardholder PAN | N21: 72_DF07 part 3
A22: 250331162609 | B22: XXX | C22: Context | D22: cardContext | E22: minimumLengthOfPAN | F22: Max2AlphaNumericText | J22: Minimum length of cardholder PAN | N22: 72_DF07 part 2
A23: 250410114325 | B23: XXX | C23: Context | D23: cardContext | E23: newSecretCodeIndicator | F23: TrueFalseIndicator | J23: TrueFalseIndicator
A24: 250331162611 | B24: XXX | C24: Context | D24: cardContext | E24: pinEntryTimer | F24: Exact2AlphaNumericText | J24: PIN entry timer | N24: 72_DF07 part 4
A25: 250331162612 | B25: XXX | C25: Context | D25: cardContext | E25: processingModeForNSCardApplicationCurrency | F25: Exact1AlphaNumericText | J25: Processing mode for non-supported card application currency | N25: 72_DF07 part 6
A26: 250410114324 | B26: XXX | C26: Context | D26: cardContext | E26: remanufacturingIndicator | F26: TrueFalseIndicator | J26: TrueFalseIndicator
A27: 250410114319 | B27: XXX | C27: Context | D27: cardContext | E27: secretCodeChoiceIndicator | F27: TrueFalseIndicator | J27: Indicateur du nouveaux code secret
A28: 250331114324 | B28: XXX | C28: Context | D28: cardContext | E28: secretCodeKnownIndicator | F28: TrueFalseIndicator | J28: Indicates if the secret code is known by the illegitimate holder of the card
A29: 250331114320 | B29: XXX | C29: Context | D29: cardContext | E29: semanticCheckIndicator | F29: TrueFalseIndicator | J29: Indicates if the action is a check or real action on card (Card activation)
A30: 250425201501 | C30: Context | D30: cardContext | E30: temp_applicationAIDLength | F30: Exact2NumericText | J30: Application AID length | N30: 72_DF8B part 2 | S30: OUI
A31: 250425201031 | C31: Context | D31: cardContext | E31: temp_cardProductLength | F31: Exact1HexBinaryText | J31: Card product length | N31: 72_DF49 part 3 | S31: OUI
A32: 250425201032 | C32: Context | D32: cardContext | E32: temp_cardProductValue | F32: Max5HexBinaryText | J32: Card product value | N32: 72_DF49 part 4 | S32: OUI
A33: 250425201508 | C33: Context | D33: cardContext | E33: temp_cVMSupported | F33: Exact1HexBinaryText | J33: CVM supported | N33: 72_DF89 part 1 | S33: OUI
A34: 250425201518 | C34: Context | D34: cardContext | E34: temp_cVMSupportedNoCvmRequired | F34: Exact1HexBinaryText | J34: CVM supported – No CVM Required | N34: 72_DFA9 part 5 | S34: OUI
A35: 250425200709 | C35: Context | D35: cardContext | E35: temp_defaultEMVDolsForAnEMVCardApplication | F35: DefaultEMVDolsForAnEMVCardApplicationCodeset | J35: DOL type | N35: 72_DF1A part 3 | S35: OUI
A36: 250425201506 | C36: Context | D36: cardContext | E36: temp_noOnDeviceCvm | F36: Exact12NumericText | J36: Reader Contactless Transaction limit (No On-Device CVM) | N36: 72_DF88 part 6 | S36: OUI
A37: 250425201507 | C37: Context | D37: cardContext | E37: temp_onDeviceCvm | F37: Exact12NumericText | J37: Reader Contactless Transaction limit (On-Device CVM) | N37: 72_DF88 part 7 | S37: OUI
A38: 250425201503 | C38: Context | D38: cardContext | E38: temp_readerContactlessFloorLimit | F38: Exact12NumericText | J38: Reader Contactless Floor limit | N38: 72_DF88 part 3 | S38: OUI
A39: 250425201505 | C39: Context | D39: cardContext | E39: temp_readerContactlessTransactionLimit | F39: Exact12NumericText | J39: Reader Contactless Transaction limit | N39: 72_DF88 part 5 | S39: OUI
A40: 250425201504 | C40: Context | D40: cardContext | E40: temp_readerCvmRequiredLimit | F40: Exact12NumericText | J40: Reader CVM Required Limit | N40: 72_DF88 part 4 | S40: OUI
A41: 250425201509 | C41: Context | D41: cardContext | E41: temp_statusCheckSupportFlag | F41: TrueFalseIndicator | J41: Status check support flag | N41: 72_DF89 part 2 | S41: OUI
...

Sheet TypesStructures
A1: Structure | B1: Attributes | C1: Typologie | D1: Explication | E1: Commentaires
A2: AdditionalDataType | B2: complement | C2: Max255Text
A3: AdditionalDataType | B3: typeData | C3: Max50Text
A4: AdditionalDataType | B4: value | C4: Max3000Text
A5: AmountType | B5: amount | C5: ImpliedCurrencyAndAmount
A6: AmountType | B6: amountDescription | C6: Max35Text | D6: Short description of amount
A7: AmountType | B7: conversionDateTime | C7: ISODateTime
A8: AmountType | B8: currency | C8: ISO3NumericCurrencyCode
A9: AmountType | B9: exchangeRate | C9: Base25OneRate
A10: AmountType | B10: originalAmount | C10: ImpliedCurrencyAndAmount
A11: AmountType | B11: originalCurrency | C11: ISO3NumericCurrencyCode
A12: ContactType | B12: email | C12: Max256Text
A13: ContactType | B13: fax | C13: PhoneNumberText
A14: ContactType | B14: language | C14: ISOMax3ALanguageCode
A15: ContactType | B15: name | C15: Max70Text
A16: ContactType | B16: phone | C16: PhoneNumberText
A17: FeesType | B17: amount | C17: ImpliedCurrencyAndAmount
A18: FeesType | B18: conversionDateTime | C18: ISODateTime
... A21: FeesType | B21: exchangeRate | C21: Base25OneRate
A22: FeesType | B22: feesDescription | C22: Max35Text | D22: Short description of the Fee amount
A23: FeesType | B23: feesDescriptor | C23: Max35Text | D23: Identification of specific fee
A24: FeesType | B24: feesNature | C24: FeesNatureCodeset
A25: FeesType | B25: feesOtherNature | C25: Max35Text | D25: Additional information for specify the type of fee
A26: FeesType | B26: feesProgram | C26: Max35Text | D26: Identification of fee program
A27: FeesType | B27: originalCurrency | C27: ISO3NumericCurrencyCode
A28: KeyValueType | B28: key | C28: Max70Text | D28: Universal usage with string
A29: KeyValueType | B29: value | C29: Max70Text | D29: Universal usage with string
A30: LimitType | B30: limitAmount | C30: ImpliedCurrencyAndAmount | D30: montant de la limite
A31: LimitType | B31: limitDescription | C31: Max35Text | D31: description de la limite
A32: LimitType | B32: limitId | C32: LimitTypeIDCodeset | D32: Identifiant de la limite
A33: MerchantIdType | B33: merchantId | C33: Max10NumericText | D33: Merchant Id
A34: MerchantIdType | B34: merchantIdUsage | C34: MerchantIdUsageCodeset | D34: Merchant Id Usage (Internal, External, CB, Visa, MC)
A35: MerchantIdType | B35: merchantName | C35: Max40Text | D35: Merchant Name
A36: PhoneNumberType | B36: phoneNumber | C36: PhoneNumberText | D36: Première partie du : ^\+?[1-9]\d{1,14}$ selon le standard international E.164
A37: PointOfSaleType | B37: id | C37: Min7Max15NumericText | D37: Identifiant
A38: PointOfSaleType | B38: name | C38: Max40Text | D38: Name
A39: PointOfSaleType | B39: postalAddress | C39: PostalAddressType | D39: Postal Address
... A53: PostalAddressType | B53: townName | C53: Max70Text | D53: Nom de la ville
A54: ProcessorCardDataType | B54: cardLevel | C54: CardLevelCodeset
A55: ProcessorCardDataType | B55: cardUsage | C55: CardUsageCodeset
...

Sheet TypesSimples
A1: Libellés | B1: Définiton | C1: Type | D1: Pattern | E1: FractionD | F1: TotalD | G1: minLength /mininclusive | H1: maxLength | I1: Commentaire
A2: 4Or6NumericText | B2: Number of objects represented as a positive integer. | C2: string | D2: ([0-9]{4}|[0-9]{6})
A3: Base25OneRate | B3: Rate expressed as a decimal | C3: string | D3: [0-9]{1,25}(\.?[0-9]{0,13})? | I3: 25 max avant la virgule et 13 max après la virgule
A4: DecimalRate | B4: decimal Amount | C4: string | D4: [0-9]{1,8}(\.?[0-9]{0,7})? | I4: 8 max avant la virgule et 7 max après la virgule
A5: Exac12AlphaNumericText | B5: 12 alphanumeric characters | C5: string | D5: [0-9A-Za-z]{12}
A6: Exact10AlphaNumericText | B6: 10 alphanumeric characters | C6: string | D6: [0-9A-Za-z]{10}
A7: Exact10NumericText | B7: Specifies a numeric string with an exact length of 10 digits. | C7: string | D7: [0-9]{10}
A8: Exact10Text | B8: 10 alphanumeric and special characters | C8: string | G8: 10 | H8: 10
A9: Exact11NumericText | B9: Specifies a numeric string with an exact length of 11 digits. | C9: string | D9: [0-9]{11}
A10: Exact11Text | B10: 11 alphanumeric and special characters | C10: string | G10: 11 | H10: 11
A11: Exact12AlphaNumericText | B11: 12 alphanumeric characters | C11: string | D11: [0-9A-Za-z]{12}
A12: Exact12NumericText | B12: Specifies a numeric string with an exact length of 12 digits. | C12: string | D12: [0-9]{12}
A13: Exact12Text | B13: 12 alphanumeric and special characters | C13: string | G13: 12 | H13: 12
A14: Exact15AlphaNumericText | B14: 15 alphanumeric characters | C14: string | D14: [0-9A-Za-z]{15}
A15: Exact15HexBinaryText | B15: Specifies a character string with an exact length of 15 binary bytes (30 hexadecimal text characters) | C15: string | D15: ([0-9A-F][0-9A-F]){15}
A16: Exact15Text | B16: 15 alphanumeric and special characters | C16: string | G16: 15 | H16: 15
A17: Exact16AlphaNumericText | B17: 16 alphanumeric characters | C17: string | D17: [0-9A-Za-z]{16}
A18: Exact16HexBinaryText | B18: Specifies a character string with an exact length of 16 binary bytes (32 hexadecimal text characters) | C18: string | D18: ([0-9A-F][0-9A-F]){16}
A19: Exact16NumericText | B19: Specifies a numeric string with an exact length of 16 digits. | C19: string | D19: [0-9]{16}
A20: Exact16Text | B20: 16 alphanumeric and special characters | C20: string | G20: 16 | H20: 16
A21: Exact19AlphaNumericText | B21: 19 alphanumeric characters | C21: string | D21: [0-9A-Za-z]{19}
A22: Exact19HexBinaryText | B22: Specifies a character string with an exact length of 19 binary bytes (38 hexadecimal text characters) | C22: string | D22: ([0-9A-F][0-9A-F]){19}
A23: Exact1AlphaNumericText | B23: 1 alphanumeric character | C23: string | D23: [0-9A-Za-z]{1}
A24: Exact1HexBinaryText | B24: Specifies a character string with an exact length of 1 binary bytes (2 hexadecimal text characters) | C24: string | D24: ([0-9A-F][0-9A-F]){1}
A25: Exact1NumericText | B25: Specifies a numeric string with an exact length of 1 digits. | C25: string | D25: [0-9]{1}
A26: Exact1Text | B26: Specifies a string with an exact length of 1 character | C26: string | G26: 1 | H26: 1
A27: Exact20HexBinaryText | B27: Specifies a character string with an exact length of 20 binary bytes (40 hexadecimal text characters) | C27: string | D27: ([0-9A-F][0-9A-F]){20}
A28: Exact20Text | B28: 20 alphanumeric and special characters | C28: string | G28: 20 | H28: 20
A29: Exact24Text | B29: 24 alphanumeric and special characters | C29: string | G29: 24 | H29: 24
A30: Exact252HexBinaryText | B30: Specifies a character string with an exact length of 252 binary bytes (504 hexadecimal text characters) | C30: string | D30: ([0-9A-F][0-9A-F]){252}
A31: Exact2AlphaNumericText | B31: 2 alphanumeric characters | C31: string | D31: [0-9A-Za-z]{2}
A32: Exact2HexBinaryText | B32: Specifies a character string with an exact length of 2 binary bytes (4 hexadecimal text characters) | C32: string | D32: ([0-9A-F][0-9A-F]){2}
A33: Exact2NumericText | B33: Specifies a numeric string with an exact length of 2 digits. | C33: string | D33: [0-9]{2}
A34: Exact2Text | B34: 2 alphanumeric and special characters | C34: string | G34: 2 | H34: 2
A35: Exact32Text | B35: 32 alphanumeric and special characters | C35: string | G35: 32 | H35: 32
A36: Exact36Text | B36: 36 alphanumeric and special characters | C36: string | G36: 36 | H36: 36
A37: Exact3AlphaNumericText | B37: 3 alphanumeric characters | C37: string | D37: [0-9A-Za-z]{3}
A38: Exact3HexBinaryText | B38: Specifies a character string with an exact length of 3 binary bytes (6 hexadecimal text characters) | C38: string | D38: ([0-9A-F][0-9A-F]){3}
A39: Exact3NumericText | B39: Specifies a numeric string with an exact length of 3 digits. | C39: string | D39: [0-9]{3}
A40: Exact3Text | B40: 3 alphanumeric and special characters | C40: string | G40: 3 | H40: 3
...

Sheet Codeset
A1: CODE SET - LISTE DE VALEURS AUTORISEES POUR LE TYPE DE CHAMP
A2: Code Set | B2: Format | C2: Data | D2: Data Comment
A3: AcceptanceChannelCodeset | B3: Exact4Text | C3: FFPM | D3: Face to face payment
A4: AcceptanceChannelCodeset | B4: Exact4Text | C4: RMPM | D4: Remote payment
A5: AcceptanceChannelCodeset | B5: Exact4Text | C5: UTPM | D5: Unattended payment
A6: AcceptanceSystemCurrentConnectingModeCodeset | B6: Exact4Text | C6: LAIP | D6: LAN IP
A7: AcceptanceSystemCurrentConnectingModeCodeset | B7: Exact4Text | C7: RTIP | D7: RTC NAS IP
A8: AcceptanceSystemCurrentConnectingModeCodeset | B8: Exact4Text | C8: RTPA | D8: RTC PAD X25
A9: AcceptanceSystemCurrentConnectingModeCodeset | B9: Exact4Text | C9: DELI | D9: X25 dedicated line
A10: AcceptanceSystemCurrentConnectingModeCodeset | B10: Exact4Text | C10: RNBC | D10: RNIS B canal (EBS)
A11: AcceptanceSystemCurrentConnectingModeCodeset | B11: Exact4Text | C11: RNDC | D11: RNIS D canal X25
A12: AcceptanceSystemCurrentConnectingModeCodeset | B12: Exact4Text | C12: GSMX | D12: GSM X25
A13: AcceptanceSystemCurrentConnectingModeCodeset | B13: Exact4Text | C13: GSMI | D13: GSM IP
... A113: AuthorisationForcingCodeCodeset | B113: Exact4Text | C113: NOFO | D113: No forcing
A114: BlacklistDistributionRegionsCodeset | B114: Exact2Text | C114: RZ
A115: BlacklistDistributionRegionsCodeset | B115: Exact2Text | C115: RD
A116: BlacklistDistributionRegionsCodeset | B116: Exact2Text | C116: RN
A117: BlockingReasonCodeset | B117: Max50Text | C117: BLOCKING_REASON_1
A118: BlockingReasonCodeset | B118: Max50Text | C118: BLOCKING_REASON_2
A119: BlockingRegulatoryReasonCodeset | B119: Max50Text | C119: REG_BLOCKING_REASON_1
A120: BlockingRegulatoryReasonCodeset | B120: Max50Text | C120: REG_BLOCKING_REASON_2
A121: BrandCodeset | B121: Exact4Text | C121: CBFR | D121: CB
A122: BrandCodeset | B122: Exact4Text | C122: VISA | D122: VISA
A123: BrandCodeset | B123: Exact4Text | C123: MACD | D123: Mastercard
A124: BrandCodeset | B124: Exact4Text | C124: DISC | D124: Discover
A125: BrandCodeset | B125: Exact4Text | C125: UPIC | D125: UPI
A126: BrandCodeset | B126: Exact4Text | C126: VPAY | D126: VPAY
A127: BrandCodeset | B127: Exact4Text | C127: ELEC | D127: Electron
A128: BrandCodeset | B128: Exact4Text | C128: MSTR | D128: Maestro
A129: BrandCodeset | B129: Exact4Text | C129: JCB0 | D129: JCB
A130: BrandCodeset | B130: Exact4Text | C130: REPV | D130: Reserved for private use
A131: BuyingMethodCodeset | B131: Exact4Text | C131: INAP | D131: In-app payment
A132: BuyingMethodCodeset | B132: Exact4Text | C132: BRWS | D132: Browser-based payment
... A135: CardAcceptorArchitectureCategoryCodeset | B135: Exact4Text | C135: DICL | D135: Distributed (clustered)
A136: CardAgreementDeferredCalendarCodeset | B136: Max50Text | C136: LAST_DAY_ON_MONTH
A137: CardAgreementDeferredCalendarCodeset | B137: Max50Text | C137: FIRST_DAY_ON_MONTH
A138: CardAgreementDeferredCalendarCodeset | B138: Max50Text | C138: MIDDLE_DAY_ON_MONTH
A139: CardApplicationCodeset | B139: Exact4Text | C139: EMVC | D139: EMV
A140: CardApplicationCodeset | B140: Exact4Text | C140: CIMG | D140: Contactless integrated circuit - magstripe context
A141: CardDataEntryModeCodeset | B141: Exact4Text | C141: NOTS | D141: Not specified
...

Sheet DICO_NomsCourts
A2: Objet-N0 - Nom long | B2: Objet-N1 - Nom long | C2: Objet-N2 - Nom long | D2: Objet-N3 - Nom long | E2: Objet_N0 - Nom Court | F2: Objet_N1 - Nom Court | G2: Objet_N2 - Nom Court | H2: Objet_N3 - Nom Court
A3: =DICO_Export!D3 -> error | B3: =DICO_Export!E3 -> code | C3: =#REF! -> #REF! | D3: =#REF! -> #REF! | E3: =LEFT(A3,1)&SUBSTITUTE(SUBSTITUTE(SUBSTITUTE(SUBSTITUTE(SUBSTITUTE(SUBSTITUTE(SUBSTITUTE(RIGHT(A3,LEN(A3)-1),"a"," "),"e"," "),"i"," "),"o"," "),"u"," "),"y"," ")," ","") -> errr | F3: =LEFT(B3,1)&SUBSTITUTE(SUBSTITUTE(SUBSTITUTE(SUBSTITUTE(SUBSTITUTE(SUBSTITUTE(SUBSTITUTE(RIGHT(B3,LEN(B3)-1),"a"," "),"e"," "),"i"," "),"o"," "),"u"," "),"y"," ")," ","") -> cd | G3: =LEFT(C3,1)&SUBSTITUTE(SUBSTITUTE(SUBSTITUTE(SUBSTITUTE(SUBSTITUTE(SUBSTITUTE(SUBSTITUTE(RIGHT(C3,LEN(C3)-1),"a"," "),"e"," "),"i"," "),"o"," "),"u"," "),"y"," ")," ","") -> #REF! | H3: =LEFT(D3,1)&SUBSTITUTE(SUBSTITUTE(SUBSTITUTE(SUBSTITUTE(SUBSTITUTE(SUBSTITUTE(SUBSTITUTE(RIGHT(D3,LEN(D3)-1),"a"," "),"e"," "),"i"," "),"o"," "),"u"," "),"y"," ")," ","") -> #REF!
A4: =DICO_Export!D4 -> error | B4: =DICO_Export!E4 -> developerText | C4: =#REF! -> #REF! | D4: =#REF! -> #REF! | E4: =LEFT(A4,1)&SUBSTITUTE(SUBSTITUTE(SUBSTITUTE(SUBSTITUTE(SUBSTITUTE(SUBSTITUTE(SUBSTITUTE(RIGHT(A4,LEN(A4)-1),"a"," "),"e"," "),"i"," "),"o"," "),"u"," "),"y"," ")," ","") -> errr | F4: =LEFT(B4,1)&SUBSTITUTE(SUBSTITUTE(SUBSTITUTE(SUBSTITUTE(SUBSTITUTE(SUBSTITUTE(SUBSTITUTE(RIGHT(B4,LEN(B4)-1),"a"," "),"e"," "),"i"," "),"o"," "),"u"," "),"y"," ")," ","") -> dvlprTxt | G4: =LEFT(C4,1)&SUBSTITUTE(SUBSTITUTE(SUBSTITUTE(SUBSTITUTE(SUBSTITUTE(SUBSTITUTE(SUBSTITUTE(RIGHT(C4,LEN(C4)-1),"a"," "),"e"," "),"i"," "),"o"," "),"u"," "),"y"," ")," ","") -> #REF! | H4: =LEFT(D4,1)&SUBSTITUTE(SUBSTITUTE(SUBSTITUTE(SUBSTITUTE(SUBSTITUTE(SUBSTITUTE(SUBSTITUTE(RIGHT(D4,LEN(D4)-1),"a"," "),"e"," "),"i"," "),"o"," "),"u"," "),"y"," ")," ","") -> #REF!
A5: =DICO_Export!D5 -> error | B5: =DICO_Export!E5 -> moreInfo | C5: =#REF! -> #REF! | D5: =#REF! -> #REF! | E5: =LEFT(A5,1)&SUBSTITUTE(SUBSTITUTE(SUBSTITUTE(SUBSTITUTE(SUBSTITUTE(SUBSTITUTE(SUBSTITUTE(RIGHT(A5,LEN(A5)-1),"a"," "),"e"," "),"i"," "),"o"," "),"u"," "),"y"," ")," ","") -> errr | F5: =LEFT(B5,1)&SUBSTITUTE(SUBSTITUTE(SUBSTITUTE(SUBSTITUTE(SUBSTITUTE(SUBSTITUTE(SUBSTITUTE(RIGHT(B5,LEN(B5)-1),"a"," "),"e"," "),"i"," "),"o"," "),"u"," "),"y"," ")," ","") -> mrInf | G5: =LEFT(C5,1)&SUBSTITUTE(SUBSTITUTE(SUBSTITUTE(SUBSTITUTE(SUBSTITUTE(SUBSTITUTE(SUBSTITUTE(RIGHT(C5,LEN(C5)-1),"a"," "),"e"," "),"i"," "),"o"," "),"u"," "),"y"," ")," ","") -> #REF! | H5: =LEFT(D5,1)&SUBSTITUTE(SUBSTITUTE(SUBSTITUTE(SUBSTITUTE(SUBSTITUTE(SUBSTITUTE(SUBSTITUTE(RIGHT(D5,LEN(D5)-1),"a"," "),"e"," "),"i"," "),"o"," "),"u"," "),"y"," ")," ","") -> #REF!
A6: =DICO_Export!D6 -> error | B6: =DICO_Export!E6 -> text | C6: =#REF! -> #REF! | D6: =#REF! -> #REF! | E6: =LEFT(A6,1)&SUBSTITUTE(SUBSTITUTE(SUBSTITUTE(SUBSTITUTE(SUBSTITUTE(SUBSTITUTE(SUBSTITUTE(RIGHT(A6,LEN(A6)-1),"a"," "),"e"," "),"i"," "),"o"," "),"u"," "),"y"," ")," ","") -> errr | F6: =LEFT(B6,1)&SUBSTITUTE(SUBSTITUTE(SUBSTITUTE(SUBSTITUTE(SUBSTITUTE(SUBSTITUTE(SUBSTITUTE(RIGHT(B6,LEN(B6)-1),"a"," "),"e"," "),"i"," "),"o"," "),"u"," "),"y"," ")," ","") -> txt | G6: =LEFT(C6,1)&SUBSTITUTE(SUBSTITUTE(SUBSTITUTE(SUBSTITUTE(SUBSTITUTE(SUBSTITUTE(SUBSTITUTE(RIGHT(C6,LEN(C6)-1),"a"," "),"e"," "),"i"," "),"o"," "),"u"," "),"y"," ")," ","") -> #REF! | H6: =LEFT(D6,1)&SUBSTITUTE(SUBSTITUTE(SUBSTITUTE(SUBSTITUTE(SUBSTITUTE(SUBSTITUTE(SUBSTITUTE(RIGHT(D6,LEN(D6)-1),"a"," "),"e"," "),"i"," "),"o"," "),"u"," "),"y"," ")," ","") -> #REF!
A7: =DICO_Export!D7 -> httpStatus | B7: =DICO_Export!E7 -> httpCode | C7: =#REF! -> #REF! | D7: =#REF! -> #REF! | E7: =LEFT(A7,1)&SUBSTITUTE(SUBSTITUTE(SUBSTITUTE(SUBSTITUTE(SUBSTITUTE(SUBSTITUTE(SUBSTITUTE(RIGHT(A7,LEN(A7)-1),"a"," "),"e"," "),"i"," "),"o"," "),"u"," "),"y"," ")," ","") -> httpStts | F7: =LEFT(B7,1)&SUBSTITUTE(SUBSTITUTE(SUBSTITUTE(SUBSTITUTE(SUBSTITUTE(SUBSTITUTE(SUBSTITUTE(RIGHT(B7,LEN(B7)-1),"a"," "),"e"," "),"i"," "),"o"," "),"u"," "),"y"," ")," ","") -> httpCd | G7: =LEFT(C7,1)&SUBSTITUTE(SUBSTITUTE(SUBSTITUTE(SUBSTITUTE(SUBSTITUTE(SUBSTITUTE(SUBSTITUTE(RIGHT(C7,LEN(C7)-1),"a"," "),"e"," "),"i"," "),"o"," "),"u"," "),"y"," ")," ","") -> #REF! | H7: =LEFT(D7,1)&SUBSTITUTE(SUBSTITUTE(SUBSTITUTE(SUBSTITUTE(SUBSTITUTE(SUBSTITUTE(SUBSTITUTE(RIGHT(D7,LEN(D7)-1),"a"," "),"e"," "),"i"," "),"o"," "),"u"," "),"y"," ")," ","") -> #REF!
A8: =DICO_Export!D8 -> httpStatus | B8: =DICO_Export!E8 -> requestId | C8: =#REF! -> #REF! | D8: =#REF! -> #REF! | E8: =LEFT(A8,1)&SUBSTITUTE(SUBSTITUTE(SUBSTITUTE(SUBSTITUTE(SUBSTITUTE(SUBSTITUTE(SUBSTITUTE(RIGHT(A8,LEN(A8)-1),"a"," "),"e"," "),"i"," "),"o"," "),"u"," "),"y"," ")," ","") -> httpStts | F8: =LEFT(B8,1)&SUBSTITUTE(SUBSTITUTE(SUBSTITUTE(SUBSTITUTE(SUBSTITUTE(SUBSTITUTE(SUBSTITUTE(RIGHT(B8,LEN(B8)-1),"a"," "),"e"," "),"i"," "),"o"," "),"u"," "),"y"," ")," ","") -> rqstId | G8: =LEFT(C8,1)&SUBSTITUTE(SUBSTITUTE(SUBSTITUTE(SUBSTITUTE(SUBSTITUTE(SUBSTITUTE(SUBSTITUTE(RIGHT(C8,LEN(C8)-1),"a"," "),"e"," "),"i"," "),"o"," "),"u"," "),"y"," ")," ","") -> #REF! | H8: =LEFT(D8,1)&SUBSTITUTE(SUBSTITUTE(SUBSTITUTE(SUBSTITUTE(SUBSTITUTE(SUBSTITUTE(SUBSTITUTE(RIGHT(D8,LEN(D8)-1),"a"," "),"e"," "),"i"," "),"o"," "),"u"," "),"y"," ")," ","") -> #REF!
A9: =DICO_Export!D9 -> cardContext | B9: =DICO_Export!E9 -> acquiringChannel | C9: =#REF! -> #REF! | D9: =#REF! -> #REF! | E9: =LEFT(A9,1)&SUBSTITUTE(SUBSTITUTE(SUBSTITUTE(SUBSTITUTE(SUBSTITUTE(SUBSTITUTE(SUBSTITUTE(RIGHT(A9,LEN(A9)-1),"a"," "),"e"," "),"i"," "),"o"," "),"u"," "),"y"," ")," ","") -> crdCntxt | F9: =LEFT(B9,1)&SUBSTITUTE(SUBSTITUTE(SUBSTITUTE(SUBSTITUTE(SUBSTITUTE(SUBSTITUTE(SUBSTITUTE(RIGHT(B9,LEN(B9)-1),"a"," "),"e"," "),"i"," "),"o"," "),"u"," "),"y"," ")," ","") -> acqrngChnnl | G9: =LEFT(C9,1)&SUBSTITUTE(SUBSTITUTE(SUBSTITUTE(SUBSTITUTE(SUBSTITUTE(SUBSTITUTE(SUBSTITUTE(RIGHT(C9,LEN(C9)-1),"a"," "),"e"," "),"i"," "),"o"," "),"u"," "),"y"," ")," ","") -> #REF! | H9: =LEFT(D9,1)&SUBSTITUTE(SUBSTITUTE(SUBSTITUTE(SUBSTITUTE(SUBSTITUTE(SUBSTITUTE(SUBSTITUTE(RIGHT(D9,LEN(D9)-1),"a"," "),"e"," "),"i"," "),"o"," "),"u"," "),"y"," ")," ","") -> #REF!
A10: =DICO_Export!D10 -> cardContext | B10: =DICO_Export!E10 -> actionOnCard | C10: =#REF! -> #REF! | D10: =#REF! -> #REF! | E10: =LEFT(A10,1)&SUBSTITUTE(SUBSTITUTE(SUBSTITUTE(SUBSTITUTE(SUBSTITUTE(SUBSTITUTE(SUBSTITUTE(RIGHT(A10,LEN(A10)-1),"a"," "),"e"," "),"i"," "),"o"," "),"u"," "),"y"," ")," ","") -> crdCntxt | F10: =LEFT(B10,1)&SUBSTITUTE(SUBSTITUTE(SUBSTITUTE(SUBSTITUTE(SUBSTITUTE(SUBSTITUTE(SUBSTITUTE(RIGHT(B10,LEN(B10)-1),"a"," "),"e"," "),"i"," "),"o"," "),"u"," "),"y"," ")," ","") -> actnOnCrd | G10: =LEFT(C10,1)&SUBSTITUTE(SUBSTITUTE(SUBSTITUTE(SUBSTITUTE(SUBSTITUTE(SUBSTITUTE(SUBSTITUTE(RIGHT(C10,LEN(C10)-1),"a"," "),"e"," "),"i"," "),"o"," "),"u"," "),"y"," ")," ","") -> #REF! | H10: =LEFT(D10,1)&SUBSTITUTE(SUBSTITUTE(SUBSTITUTE(SUBSTITUTE(SUBSTITUTE(SUBSTITUTE(SUBSTITUTE(RIGHT(D10,LEN(D10)-1),"a"," "),"e"," "),"i"," "),"o"," "),"u"," "),"y"," ")," ","") -> #REF!
A11: =DICO_Export!D11 -> cardContext | B11: =DICO_Export!E11 -> activationCodeForNoShowInvoice | C11: =#REF! -> #REF! | D11: =#REF! -> #REF! | E11: =LEFT(A11,1)&SUBSTITUTE(SUBSTITUTE(SUBSTITUTE(SUBSTITUTE(SUBSTITUTE(SUBSTITUTE(SUBSTITUTE(RIGHT(A11,LEN(A11)-1),"a"," "),"e"," "),"i"," "),"o"," "),"u"," "),"y"," ")," ","") -> crdCntxt | F11: =LEFT(B11,1)&SUBSTITUTE(SUBSTITUTE(SUBSTITUTE(SUBSTITUTE(SUBSTITUTE(SUBSTITUTE(SUBSTITUTE(RIGHT(B11,LEN(B11)-1),"a"," "),"e"," "),"i"," "),"o"," "),"u"," "),"y"," ")," ","") -> actvtnCdFrNShwInvc | G11: =LEFT(C11,1)&SUBSTITUTE(SUBSTITUTE(SUBSTITUTE(SUBSTITUTE(SUBSTITUTE(SUBSTITUTE(SUBSTITUTE(RIGHT(C11,LEN(C11)-1),"a"," "),"e"," "),"i"," "),"o"," "),"u"," "),"y"," ")," ","") -> #REF! | H11: =LEFT(D11,1)&SUBSTITUTE(SUBSTITUTE(SUBSTITUTE(SUBSTITUTE(SUBSTITUTE(SUBSTITUTE(SUBSTITUTE(RIGHT(D11,LEN(D11)-1),"a"," "),"e"," "),"i"," "),"o"," "),"u"," "),"y"," ")," ","") -> #REF!
A12: =DICO_Export!D12 -> cardContext | B12: =DICO_Export!E12 -> activCodePLBSInvoiceRemoteModeOrPreAuthProlongTransaction | C12: =#REF! -> #REF! | D12: =#REF! -> #REF! | E12: =LEFT(A12,1)&SUBSTITUTE(SUBSTITUTE(SUBSTITUTE(SUBSTITUTE(SUBSTITUTE(SUBSTITUTE(SUBSTITUTE(RIGHT(A12,LEN(A12)-1),"a"," "),"e"," "),"i"," "),"o"," "),"u"," "),"y"," ")," ","") -> crdCntxt | F12: =LEFT(B12,1)&SUBSTITUTE(SUBSTITUTE(SUBSTITUTE(SUBSTITUTE(SUBSTITUTE(SUBSTITUTE(SUBSTITUTE(RIGHT(B12,LEN(B12)-1),"a"," "),"e"," "),"i"," "),"o"," "),"u"," "),"y"," ")," ","") -> actvCdPLBSInvcRmtMdOrPrAthPrlngTrnsctn | G12: =LEFT(C12,1)&SUBSTITUTE(SUBSTITUTE(SUBSTITUTE(SUBSTITUTE(SUBSTITUTE(SUBSTITUTE(SUBSTITUTE(RIGHT(C12,LEN(C12)-1),"a"," "),"e"," "),"i"," "),"o"," "),"u"," "),"y"," ")," ","") -> #REF! | H12: =LEFT(D12,1)&SUBSTITUTE(SUBSTITUTE(SUBSTITUTE(SUBSTITUTE(SUBSTITUTE(SUBSTITUTE(SUBSTITUTE(RIGHT(D12,LEN(D12)-1),"a"," "),"e"," "),"i"," "),"o"," "),"u"," "),"y"," ")," ","") -> #REF!
A13: =DICO_Export!D13 -> cardContext | B13: =DICO_Export!E13 -> additionalInvoiceActivationCode | C13: =#REF! -> #REF! | D13: =#REF! -> #REF! | E13: =LEFT(A13,1)&SUBSTITUTE(SUBSTITUTE(SUBSTITUTE(SUBSTITUTE(SUBSTITUTE(SUBSTITUTE(SUBSTITUTE(RIGHT(A13,LEN(A13)-1),"a"," "),"e"," "),"i"," "),"o"," "),"u"," "),"y"," ")," ","") -> crdCntxt | F13: =LEFT(B13,1)&SUBSTITUTE(SUBSTITUTE(SUBSTITUTE(SUBSTITUTE(SUBSTITUTE(SUBSTITUTE(SUBSTITUTE(RIGHT(B13,LEN(B13)-1),"a"," "),"e"," "),"i"," "),"o"," "),"u"," "),"y"," ")," ","") -> addtnlInvcActvtnCd | G13: =LEFT(C13,1)&SUBSTITUTE(SUBSTITUTE(SUBSTITUTE(SUBSTITUTE(SUBSTITUTE(SUBSTITUTE(SUBSTITUTE(RIGHT(C13,LEN(C13)-1),"a"," "),"e"," "),"i"," "),"o"," "),"u"," "),"y"," ")," ","") -> #REF! | H13: =LEFT(D13,1)&SUBSTITUTE(SUBSTITUTE(SUBSTITUTE(SUBSTITUTE(SUBSTITUTE(SUBSTITUTE(SUBSTITUTE(RIGHT(D13,LEN(D13)-1),"a"," "),"e"," "),"i"," "),"o"," "),"u"," "),"y"," ")," ","") -> #REF!
A14: =DICO_Export!D14 -> cardContext | B14: =DICO_Export!E14 -> blockingReasonCode | C14: =#REF! -> #REF! | D14: =#REF! -> #REF! | E14: =LEFT(A14,1)&SUBSTITUTE(SUBSTITUTE(SUBSTITUTE(SUBSTITUTE(SUBSTITUTE(SUBSTITUTE(SUBSTITUTE(RIGHT(A14,LEN(A14)-1),"a"," "),"e"," "),"i"," "),"o"," "),"u"," "),"y"," ")," ","") -> crdCntxt | F14: =LEFT(B14,1)&SUBSTITUTE(SUBSTITUTE(SUBSTITUTE(SUBSTITUTE(SUBSTITUTE(SUBSTITUTE(SUBSTITUTE(RIGHT(B14,LEN(B14)-1),"a"," "),"e"," "),"i"," "),"o"," "),"u"," "),"y"," ")," ","") -> blckngRsnCd | G14: =LEFT(C14,1)&SUBSTITUTE(SUBSTITUTE(SUBSTITUTE(SUBSTITUTE(SUBSTITUTE(SUBSTITUTE(SUBSTITUTE(RIGHT(C14,LEN(C14)-1),"a"," "),"e"," "),"i"," "),"o"," "),"u"," "),"y"," ")," ","") -> #REF! | H14: =LEFT(D14,1)&SUBSTITUTE(SUBSTITUTE(SUBSTITUTE(SUBSTITUTE(SUBSTITUTE(SUBSTITUTE(SUBSTITUTE(RIGHT(D14,LEN(D14)-1),"a"," "),"e"," "),"i"," "),"o"," "),"u"," "),"y"," ")," ","") -> #REF!
... A446: =DICO_Export!D446 -> merchant | B446: =DICO_Export!E446 -> singleContractIndicator | C446: =#REF! -> #REF! | D446: =#REF! -> #REF! | E446: =LEFT(A446,1)&SUBSTITUTE(SUBSTITUTE(SUBSTITUTE(SUBSTITUTE(SUBSTITUTE(SUBSTITUTE(SUBSTITUTE(RIGHT(A446,LEN(A446)-1),"a"," "),"e"," "),"i"," "),"o"," "),"u"," "),"y"," ")," ","") -> mrchnt | F446: =LEFT(B446,1)&SUBSTITUTE(SUBSTITUTE(SUBSTITUTE(SUBSTITUTE(SUBSTITUTE(SUBSTITUTE(SUBSTITUTE(RIGHT(B446,LEN(B446)-1),"a"," "),"e"," "),"i"," "),"o"," "),"u"," "),"y"," ")," ","") -> snglCntrctIndctr | G446: =LEFT(C446,1)&SUBSTITUTE(SUBSTITUTE(SUBSTITUTE(SUBSTITUTE(SUBSTITUTE(SUBSTITUTE(SUBSTITUTE(RIGHT(C446,LEN(C446)-1),"a"," "),"e"," "),"i"," "),"o"," "),"u"," "),"y"," ")," ","") -> #REF! | H446: =LEFT(D446,1)&SUBSTITUTE(SUBSTITUTE(SUBSTITUTE(SUBSTITUTE(SUBSTITUTE(SUBSTITUTE(SUBSTITUTE(RIGHT(D446,LEN(D446)-1),"a"," "),"e"," "),"i"," "),"o"," "),"u"," "),"y"," ")," ","") -> #REF!
A447: =DICO_Export!#REF! -> #REF! | B447: =DICO_Export!#REF! -> #REF! | C447: =#REF! -> #REF! | D447: =#REF! -> #REF! | E447: =LEFT(A447,1)&SUBSTITUTE(SUBSTITUTE(SUBSTITUTE(SUBSTITUTE(SUBSTITUTE(SUBSTITUTE(SUBSTITUTE(RIGHT(A447,LEN(A447)-1),"a"," "),"e"," "),"i"," "),"o"," "),"u"," "),"y"," ")," ","") -> #REF! | F447: =LEFT(B447,1)&SUBSTITUTE(SUBSTITUTE(SUBSTITUTE(SUBSTITUTE(SUBSTITUTE(SUBSTITUTE(SUBSTITUTE(RIGHT(B447,LEN(B447)-1),"a"," "),"e"," "),"i"," "),"o"," "),"u"," "),"y"," ")," ","") -> #REF! | G447: =LEFT(C447,1)&SUBSTITUTE(SUBSTITUTE(SUBSTITUTE(SUBSTITUTE(SUBSTITUTE(SUBSTITUTE(SUBSTITUTE(RIGHT(C447,LEN(C447)-1),"a"," "),"e"," "),"i"," "),"o"," "),"u"," "),"y"," ")," ","") -> #REF! | H447: =LEFT(D447,1)&SUBSTITUTE(SUBSTITUTE(SUBSTITUTE(SUBSTITUTE(SUBSTITUTE(SUBSTITUTE(SUBSTITUTE(RIGHT(D447,LEN(D447)-1),"a"," "),"e"," "),"i"," "),"o"," "),"u"," "),"y"," ")," ","") -> #REF!
A448: =DICO_Export!#REF! -> #REF! | B448: =DICO_Export!#REF! -> #REF! | C448: =#REF! -> #REF! | D448: =#REF! -> #REF! | E448: =LEFT(A448,1)&SUBSTITUTE(SUBSTITUTE(SUBSTITUTE(SUBSTITUTE(SUBSTITUTE(SUBSTITUTE(SUBSTITUTE(RIGHT(A448,LEN(A448)-1),"a"," "),"e"," "),"i"," "),"o"," "),"u"," "),"y"," ")," ","") -> #REF! | F448: =LEFT(B448,1)&SUBSTITUTE(SUBSTITUTE(SUBSTITUTE(SUBSTITUTE(SUBSTITUTE(SUBSTITUTE(SUBSTITUTE(RIGHT(B448,LEN(B448)-1),"a"," "),"e"," "),"i"," "),"o"," "),"u"," "),"y"," ")," ","") -> #REF! | G448: =LEFT(C448,1)&SUBSTITUTE(SUBSTITUTE(SUBSTITUTE(SUBSTITUTE(SUBSTITUTE(SUBSTITUTE(SUBSTITUTE(RIGHT(C448,LEN(C448)-1),"a"," "),"e"," "),"i"," "),"o"," "),"u"," "),"y"," ")," ","") -> #REF! | H448: =LEFT(D448,1)&SUBSTITUTE(SUBSTITUTE(SUBSTITUTE(SUBSTITUTE(SUBSTITUTE(SUBSTITUTE(SUBSTITUTE(RIGHT(D448,LEN(D448)-1),"a"," "),"e"," "),"i"," "),"o"," "),"u"," "),"y"," ")," ","") -> #REF!
A449: =DICO_Export!#REF! -> #REF! | B449: =DICO_Export!#REF! -> #REF! | C449: =#REF! -> #REF! | D449: =#REF! -> #REF! | E449: =LEFT(A449,1)&SUBSTITUTE(SUBSTITUTE(SUBSTITUTE(SUBSTITUTE(SUBSTITUTE(SUBSTITUTE(SUBSTITUTE(RIGHT(A449,LEN(A449)-1),"a"," "),"e"," "),"i"," "),"o"," "),"u"," "),"y"," ")," ","") -> #REF! | F449: =LEFT(B449,1)&SUBSTITUTE(SUBSTITUTE(SUBSTITUTE(SUBSTITUTE(SUBSTITUTE(SUBSTITUTE(SUBSTITUTE(RIGHT(B449,LEN(B449)-1),"a"," "),"e"," "),"i"," "),"o"," "),"u"," "),"y"," ")," ","") -> #REF! | G449: =LEFT(C449,1)&SUBSTITUTE(SUBSTITUTE(SUBSTITUTE(SUBSTITUTE(SUBSTITUTE(SUBSTITUTE(SUBSTITUTE(RIGHT(C449,LEN(C449)-1),"a"," "),"e"," "),"i"," "),"o"," "),"u"," "),"y"," ")," ","") -> #REF! | H449: =LEFT(D449,1)&SUBSTITUTE(SUBSTITUTE(SUBSTITUTE(SUBSTITUTE(SUBSTITUTE(SUBSTITUTE(SUBSTITUTE(RIGHT(D449,LEN(D449)-1),"a"," "),"e"," "),"i"," "),"o"," "),"u"," "),"y"," ")," ","") -> #REF!
A450: =DICO_Export!#REF! -> #REF! | B450: =DICO_Export!#REF! -> #REF! | C450: =#REF! -> #REF! | D450: =#REF! -> #REF! | E450: =LEFT(A450,1)&SUBSTITUTE(SUBSTITUTE(SUBSTITUTE(SUBSTITUTE(SUBSTITUTE(SUBSTITUTE(SUBSTITUTE(RIGHT(A450,LEN(A450)-1),"a"," "),"e"," "),"i"," "),"o"," "),"u"," "),"y"," ")," ","") -> #REF! | F450: =LEFT(B450,1)&SUBSTITUTE(SUBSTITUTE(SUBSTITUTE(SUBSTITUTE(SUBSTITUTE(SUBSTITUTE(SUBSTITUTE(RIGHT(B450,LEN(B450)-1),"a"," "),"e"," "),"i"," "),"o"," "),"u"," "),"y"," ")," ","") -> #REF! | G450: =LEFT(C450,1)&SUBSTITUTE(SUBSTITUTE(SUBSTITUTE(SUBSTITUTE(SUBSTITUTE(SUBSTITUTE(SUBSTITUTE(RIGHT(C450,LEN(C450)-1),"a"," "),"e"," "),"i"," "),"o"," "),"u"," "),"y"," ")," ","") -> #REF! | H450: =LEFT(D450,1)&SUBSTITUTE(SUBSTITUTE(SUBSTITUTE(SUBSTITUTE(SUBSTITUTE(SUBSTITUTE(SUBSTITUTE(RIGHT(D450,LEN(D450)-1),"a"," "),"e"," "),"i"," "),"o"," "),"u"," "),"y"," ")," ","") -> #REF!
A451: =DICO_Export!#REF! -> #REF! | B451: =DICO_Export!#REF! -> #REF! | C451: =#REF! -> #REF! | D451: =#REF! -> #REF! | E451: =LEFT(A451,1)&SUBSTITUTE(SUBSTITUTE(SUBSTITUTE(SUBSTITUTE(SUBSTITUTE(SUBSTITUTE(SUBSTITUTE(RIGHT(A451,LEN(A451)-1),"a"," "),"e"," "),"i"," "),"o"," "),"u"," "),"y"," ")," ","") -> #REF! | F451: =LEFT(B451,1)&SUBSTITUTE(SUBSTITUTE(SUBSTITUTE(SUBSTITUTE(SUBSTITUTE(SUBSTITUTE(SUBSTITUTE(RIGHT(B451,LEN(B451)-1),"a"," "),"e"," "),"i"," "),"o"," "),"u"," "),"y"," ")," ","") -> #REF! | G451: =LEFT(C451,1)&SUBSTITUTE(SUBSTITUTE(SUBSTITUTE(SUBSTITUTE(SUBSTITUTE(SUBSTITUTE(SUBSTITUTE(RIGHT(C451,LEN(C451)-1),"a"," "),"e"," "),"i"," "),"o"," "),"u"," "),"y"," ")," ","") -> #REF! | H451: =LEFT(D451,1)&SUBSTITUTE(SUBSTITUTE(SUBSTITUTE(SUBSTITUTE(SUBSTITUTE(SUBSTITUTE(SUBSTITUTE(RIGHT(D451,LEN(D451)-1),"a"," "),"e"," "),"i"," "),"o"," "),"u"," "),"y"," ")," ","") -> #REF!
A452: =DICO_Export!D447 -> merchant | B452: =DICO_Export!E447 -> temp_anonymousDynamicPlaque | C452: =#REF! -> #REF! | D452: =#REF! -> #REF! | E452: =LEFT(A452,1)&SUBSTITUTE(SUBSTITUTE(SUBSTITUTE(SUBSTITUTE(SUBSTITUTE(SUBSTITUTE(SUBSTITUTE(RIGHT(A452,LEN(A452)-1),"a"," "),"e"," "),"i"," "),"o"," "),"u"," "),"y"," ")," ","") -> mrchnt | F452: =LEFT(B452,1)&SUBSTITUTE(SUBSTITUTE(SUBSTITUTE(SUBSTITUTE(SUBSTITUTE(SUBSTITUTE(SUBSTITUTE(RIGHT(B452,LEN(B452)-1),"a"," "),"e"," "),"i"," "),"o"," "),"u"," "),"y"," ")," ","") -> tmp_nnmsDnmcPlq | G452: =LEFT(C452,1)&SUBSTITUTE(SUBSTITUTE(SUBSTITUTE(SUBSTITUTE(SUBSTITUTE(SUBSTITUTE(SUBSTITUTE(RIGHT(C452,LEN(C452)-1),"a"," "),"e"," "),"i"," "),"o"," "),"u"," "),"y"," ")," ","") -> #REF! | H452: =LEFT(D452,1)&SUBSTITUTE(SUBSTITUTE(SUBSTITUTE(SUBSTITUTE(SUBSTITUTE(SUBSTITUTE(SUBSTITUTE(RIGHT(D452,LEN(D452)-1),"a"," "),"e"," "),"i"," "),"o"," "),"u"," "),"y"," ")," ","") -> #REF!
